2018-12-28 16:51:29,119 ERROR: Exception on /api/users/1 [GET] [in e:\myproject\gui\venv\lib\site-packages\flask\app.py:1761]
Traceback (most recent call last):
  File "e:\myproject\gui\venv\lib\site-packages\flask\app.py", line 2292, in wsgi_app
    response = self.full_dispatch_request()
  File "e:\myproject\gui\venv\lib\site-packages\flask\app.py", line 1815, in full_dispatch_request
    rv = self.handle_user_exception(e)
  File "e:\myproject\gui\venv\lib\site-packages\flask\app.py", line 1718, in handle_user_exception
    reraise(exc_type, exc_value, tb)
  File "e:\myproject\gui\venv\lib\site-packages\flask\_compat.py", line 35, in reraise
    raise value
  File "e:\myproject\gui\venv\lib\site-packages\flask\app.py", line 1813, in full_dispatch_request
    rv = self.dispatch_request()
  File "e:\myproject\gui\venv\lib\site-packages\flask\app.py", line 1799, in dispatch_request
    return self.view_functions[rule.endpoint](**req.view_args)
  File "E:\MyProject\Python\microblog\app\api\users.py", line 7, in get_user
    return jsonify(User.query.get_or_404(id).to_dict())
  File "E:\MyProject\Python\microblog\app\models.py", line 188, in to_dict
    'last_seen': self.last_seen.isoformat() + 'Z',
AttributeError: 'NoneType' object has no attribute 'isoformat'
2018-12-28 16:56:48,252 INFO: Microblog startup [in E:\MyProject\Python\microblog\app\__init__.py:86]
2018-12-28 16:57:02,073 ERROR: Exception on /api/users/1 [GET] [in e:\myproject\gui\venv\lib\site-packages\flask\app.py:1761]
Traceback (most recent call last):
  File "e:\myproject\gui\venv\lib\site-packages\sqlalchemy\engine\base.py", line 1193, in _execute_context
    context)
  File "e:\myproject\gui\venv\lib\site-packages\sqlalchemy\engine\default.py", line 509, in do_execute
    cursor.execute(statement, parameters)
sqlite3.OperationalError: no such column: user.token

The above exception was the direct cause of the following exception:

Traceback (most recent call last):
  File "e:\myproject\gui\venv\lib\site-packages\flask\app.py", line 2292, in wsgi_app
    response = self.full_dispatch_request()
  File "e:\myproject\gui\venv\lib\site-packages\flask\app.py", line 1815, in full_dispatch_request
    rv = self.handle_user_exception(e)
  File "e:\myproject\gui\venv\lib\site-packages\flask\app.py", line 1718, in handle_user_exception
    reraise(exc_type, exc_value, tb)
  File "e:\myproject\gui\venv\lib\site-packages\flask\_compat.py", line 35, in reraise
    raise value
  File "e:\myproject\gui\venv\lib\site-packages\flask\app.py", line 1813, in full_dispatch_request
    rv = self.dispatch_request()
  File "e:\myproject\gui\venv\lib\site-packages\flask\app.py", line 1799, in dispatch_request
    return self.view_functions[rule.endpoint](**req.view_args)
  File "E:\MyProject\Python\microblog\app\api\users.py", line 7, in get_user
    return jsonify(User.query.get_or_404(id).to_dict())
  File "e:\myproject\gui\venv\lib\site-packages\flask_sqlalchemy\__init__.py", line 417, in get_or_404
    rv = self.get(ident)
  File "e:\myproject\gui\venv\lib\site-packages\sqlalchemy\orm\query.py", line 923, in get
    ident, loading.load_on_pk_identity)
  File "e:\myproject\gui\venv\lib\site-packages\sqlalchemy\orm\query.py", line 1006, in _get_impl
    return db_load_fn(self, primary_key_identity)
  File "e:\myproject\gui\venv\lib\site-packages\sqlalchemy\orm\loading.py", line 250, in load_on_pk_identity
    return q.one()
  File "e:\myproject\gui\venv\lib\site-packages\sqlalchemy\orm\query.py", line 2947, in one
    ret = self.one_or_none()
  File "e:\myproject\gui\venv\lib\site-packages\sqlalchemy\orm\query.py", line 2917, in one_or_none
    ret = list(self)
  File "e:\myproject\gui\venv\lib\site-packages\sqlalchemy\orm\query.py", line 2988, in __iter__
    return self._execute_and_instances(context)
  File "e:\myproject\gui\venv\lib\site-packages\sqlalchemy\orm\query.py", line 3011, in _execute_and_instances
    result = conn.execute(querycontext.statement, self._params)
  File "e:\myproject\gui\venv\lib\site-packages\sqlalchemy\engine\base.py", line 948, in execute
    return meth(self, multiparams, params)
  File "e:\myproject\gui\venv\lib\site-packages\sqlalchemy\sql\elements.py", line 269, in _execute_on_connection
    return connection._execute_clauseelement(self, multiparams, params)
  File "e:\myproject\gui\venv\lib\site-packages\sqlalchemy\engine\base.py", line 1060, in _execute_clauseelement
    compiled_sql, distilled_params
  File "e:\myproject\gui\venv\lib\site-packages\sqlalchemy\engine\base.py", line 1200, in _execute_context
    context)
  File "e:\myproject\gui\venv\lib\site-packages\sqlalchemy\engine\base.py", line 1413, in _handle_dbapi_exception
    exc_info
  File "e:\myproject\gui\venv\lib\site-packages\sqlalchemy\util\compat.py", line 265, in raise_from_cause
    reraise(type(exception), exception, tb=exc_tb, cause=cause)
  File "e:\myproject\gui\venv\lib\site-packages\sqlalchemy\util\compat.py", line 248, in reraise
    raise value.with_traceback(tb)
  File "e:\myproject\gui\venv\lib\site-packages\sqlalchemy\engine\base.py", line 1193, in _execute_context
    context)
  File "e:\myproject\gui\venv\lib\site-packages\sqlalchemy\engine\default.py", line 509, in do_execute
    cursor.execute(statement, parameters)
sqlalchemy.exc.OperationalError: (sqlite3.OperationalError) no such column: user.token [SQL: 'SELECT user.id AS user_id, user.username AS user_username, user.email AS user_email, user.password_hash AS user_password_hash, user.about_me AS user_about_me, user.last_seen AS user_last_seen, user.token AS user_token, user.token_expiration AS user_token_expiration, user.last_message_read_time AS user_last_message_read_time \nFROM user \nWHERE user.id = ?'] [parameters: (1,)] (Background on this error at: http://sqlalche.me/e/e3q8)
2018-12-28 16:57:34,521 ERROR: Exception on /auth/login [POST] [in e:\myproject\gui\venv\lib\site-packages\flask\app.py:1761]
Traceback (most recent call last):
  File "e:\myproject\gui\venv\lib\site-packages\sqlalchemy\engine\base.py", line 1193, in _execute_context
    context)
  File "e:\myproject\gui\venv\lib\site-packages\sqlalchemy\engine\default.py", line 509, in do_execute
    cursor.execute(statement, parameters)
sqlite3.OperationalError: no such column: user.token

The above exception was the direct cause of the following exception:

Traceback (most recent call last):
  File "e:\myproject\gui\venv\lib\site-packages\flask\app.py", line 2292, in wsgi_app
    response = self.full_dispatch_request()
  File "e:\myproject\gui\venv\lib\site-packages\flask\app.py", line 1815, in full_dispatch_request
    rv = self.handle_user_exception(e)
  File "e:\myproject\gui\venv\lib\site-packages\flask\app.py", line 1718, in handle_user_exception
    reraise(exc_type, exc_value, tb)
  File "e:\myproject\gui\venv\lib\site-packages\flask\_compat.py", line 35, in reraise
    raise value
  File "e:\myproject\gui\venv\lib\site-packages\flask\app.py", line 1813, in full_dispatch_request
    rv = self.dispatch_request()
  File "e:\myproject\gui\venv\lib\site-packages\flask\app.py", line 1799, in dispatch_request
    return self.view_functions[rule.endpoint](**req.view_args)
  File "E:\MyProject\Python\microblog\app\auth\routes.py", line 17, in login
    user = User.query.filter_by(username=form.username.data).first()
  File "e:\myproject\gui\venv\lib\site-packages\sqlalchemy\orm\query.py", line 2888, in first
    ret = list(self[0:1])
  File "e:\myproject\gui\venv\lib\site-packages\sqlalchemy\orm\query.py", line 2680, in __getitem__
    return list(res)
  File "e:\myproject\gui\venv\lib\site-packages\sqlalchemy\orm\query.py", line 2988, in __iter__
    return self._execute_and_instances(context)
  File "e:\myproject\gui\venv\lib\site-packages\sqlalchemy\orm\query.py", line 3011, in _execute_and_instances
    result = conn.execute(querycontext.statement, self._params)
  File "e:\myproject\gui\venv\lib\site-packages\sqlalchemy\engine\base.py", line 948, in execute
    return meth(self, multiparams, params)
  File "e:\myproject\gui\venv\lib\site-packages\sqlalchemy\sql\elements.py", line 269, in _execute_on_connection
    return connection._execute_clauseelement(self, multiparams, params)
  File "e:\myproject\gui\venv\lib\site-packages\sqlalchemy\engine\base.py", line 1060, in _execute_clauseelement
    compiled_sql, distilled_params
  File "e:\myproject\gui\venv\lib\site-packages\sqlalchemy\engine\base.py", line 1200, in _execute_context
    context)
  File "e:\myproject\gui\venv\lib\site-packages\sqlalchemy\engine\base.py", line 1413, in _handle_dbapi_exception
    exc_info
  File "e:\myproject\gui\venv\lib\site-packages\sqlalchemy\util\compat.py", line 265, in raise_from_cause
    reraise(type(exception), exception, tb=exc_tb, cause=cause)
  File "e:\myproject\gui\venv\lib\site-packages\sqlalchemy\util\compat.py", line 248, in reraise
    raise value.with_traceback(tb)
  File "e:\myproject\gui\venv\lib\site-packages\sqlalchemy\engine\base.py", line 1193, in _execute_context
    context)
  File "e:\myproject\gui\venv\lib\site-packages\sqlalchemy\engine\default.py", line 509, in do_execute
    cursor.execute(statement, parameters)
sqlalchemy.exc.OperationalError: (sqlite3.OperationalError) no such column: user.token [SQL: 'SELECT user.id AS user_id, user.username AS user_username, user.email AS user_email, user.password_hash AS user_password_hash, user.about_me AS user_about_me, user.last_seen AS user_last_seen, user.token AS user_token, user.token_expiration AS user_token_expiration, user.last_message_read_time AS user_last_message_read_time \nFROM user \nWHERE user.username = ?\n LIMIT ? OFFSET ?'] [parameters: ('nishishui', 1, 0)] (Background on this error at: http://sqlalche.me/e/e3q8)
2018-12-28 17:23:46,439 INFO: Microblog startup [in E:\MyProject\Python\microblog\app\__init__.py:86]
2018-12-28 17:24:16,597 INFO: Microblog startup [in E:\MyProject\Python\microblog\app\__init__.py:86]
2018-12-28 17:24:37,628 INFO: Microblog startup [in E:\MyProject\Python\microblog\app\__init__.py:86]
