2018-12-24 20:01:29,797 ERROR: Exception on /notifications [GET] [in e:\myproject\gui\venv\lib\site-packages\flask\app.py:1761]
Traceback (most recent call last):
  File "e:\myproject\gui\venv\lib\site-packages\flask\app.py", line 2292, in wsgi_app
    response = self.full_dispatch_request()
  File "e:\myproject\gui\venv\lib\site-packages\flask\app.py", line 1815, in full_dispatch_request
    rv = self.handle_user_exception(e)
  File "e:\myproject\gui\venv\lib\site-packages\flask\app.py", line 1718, in handle_user_exception
    reraise(exc_type, exc_value, tb)
  File "e:\myproject\gui\venv\lib\site-packages\flask\_compat.py", line 35, in reraise
    raise value
  File "e:\myproject\gui\venv\lib\site-packages\flask\app.py", line 1813, in full_dispatch_request
    rv = self.dispatch_request()
  File "e:\myproject\gui\venv\lib\site-packages\flask\app.py", line 1799, in dispatch_request
    return self.view_functions[rule.endpoint](**req.view_args)
  File "e:\myproject\gui\venv\lib\site-packages\flask_login\utils.py", line 261, in decorated_view
    return func(*args, **kwargs)
  File "E:\MyProject\Python\microblog\app\main\routes.py", line 198, in notifications
    since = request.arg.get('since',0.0,type=float)
  File "e:\myproject\gui\venv\lib\site-packages\werkzeug\local.py", line 347, in __getattr__
    return getattr(self._get_current_object(), name)
AttributeError: 'Request' object has no attribute 'arg'
2018-12-24 20:01:32,288 ERROR: Exception on /notifications [GET] [in e:\myproject\gui\venv\lib\site-packages\flask\app.py:1761]
Traceback (most recent call last):
  File "e:\myproject\gui\venv\lib\site-packages\flask\app.py", line 2292, in wsgi_app
    response = self.full_dispatch_request()
  File "e:\myproject\gui\venv\lib\site-packages\flask\app.py", line 1815, in full_dispatch_request
    rv = self.handle_user_exception(e)
  File "e:\myproject\gui\venv\lib\site-packages\flask\app.py", line 1718, in handle_user_exception
    reraise(exc_type, exc_value, tb)
  File "e:\myproject\gui\venv\lib\site-packages\flask\_compat.py", line 35, in reraise
    raise value
  File "e:\myproject\gui\venv\lib\site-packages\flask\app.py", line 1813, in full_dispatch_request
    rv = self.dispatch_request()
  File "e:\myproject\gui\venv\lib\site-packages\flask\app.py", line 1799, in dispatch_request
    return self.view_functions[rule.endpoint](**req.view_args)
  File "e:\myproject\gui\venv\lib\site-packages\flask_login\utils.py", line 261, in decorated_view
    return func(*args, **kwargs)
  File "E:\MyProject\Python\microblog\app\main\routes.py", line 198, in notifications
    since = request.arg.get('since',0.0,type=float)
  File "e:\myproject\gui\venv\lib\site-packages\werkzeug\local.py", line 347, in __getattr__
    return getattr(self._get_current_object(), name)
AttributeError: 'Request' object has no attribute 'arg'
2018-12-24 20:01:39,759 ERROR: Exception on /notifications [GET] [in e:\myproject\gui\venv\lib\site-packages\flask\app.py:1761]
Traceback (most recent call last):
  File "e:\myproject\gui\venv\lib\site-packages\flask\app.py", line 2292, in wsgi_app
    response = self.full_dispatch_request()
  File "e:\myproject\gui\venv\lib\site-packages\flask\app.py", line 1815, in full_dispatch_request
    rv = self.handle_user_exception(e)
  File "e:\myproject\gui\venv\lib\site-packages\flask\app.py", line 1718, in handle_user_exception
    reraise(exc_type, exc_value, tb)
  File "e:\myproject\gui\venv\lib\site-packages\flask\_compat.py", line 35, in reraise
    raise value
  File "e:\myproject\gui\venv\lib\site-packages\flask\app.py", line 1813, in full_dispatch_request
    rv = self.dispatch_request()
  File "e:\myproject\gui\venv\lib\site-packages\flask\app.py", line 1799, in dispatch_request
    return self.view_functions[rule.endpoint](**req.view_args)
  File "e:\myproject\gui\venv\lib\site-packages\flask_login\utils.py", line 261, in decorated_view
    return func(*args, **kwargs)
  File "E:\MyProject\Python\microblog\app\main\routes.py", line 198, in notifications
    since = request.arg.get('since',0.0,type=float)
  File "e:\myproject\gui\venv\lib\site-packages\werkzeug\local.py", line 347, in __getattr__
    return getattr(self._get_current_object(), name)
AttributeError: 'Request' object has no attribute 'arg'
2018-12-24 20:01:42,273 ERROR: Exception on /notifications [GET] [in e:\myproject\gui\venv\lib\site-packages\flask\app.py:1761]
Traceback (most recent call last):
  File "e:\myproject\gui\venv\lib\site-packages\flask\app.py", line 2292, in wsgi_app
    response = self.full_dispatch_request()
  File "e:\myproject\gui\venv\lib\site-packages\flask\app.py", line 1815, in full_dispatch_request
    rv = self.handle_user_exception(e)
  File "e:\myproject\gui\venv\lib\site-packages\flask\app.py", line 1718, in handle_user_exception
    reraise(exc_type, exc_value, tb)
  File "e:\myproject\gui\venv\lib\site-packages\flask\_compat.py", line 35, in reraise
    raise value
  File "e:\myproject\gui\venv\lib\site-packages\flask\app.py", line 1813, in full_dispatch_request
    rv = self.dispatch_request()
  File "e:\myproject\gui\venv\lib\site-packages\flask\app.py", line 1799, in dispatch_request
    return self.view_functions[rule.endpoint](**req.view_args)
  File "e:\myproject\gui\venv\lib\site-packages\flask_login\utils.py", line 261, in decorated_view
    return func(*args, **kwargs)
  File "E:\MyProject\Python\microblog\app\main\routes.py", line 198, in notifications
    since = request.arg.get('since',0.0,type=float)
  File "e:\myproject\gui\venv\lib\site-packages\werkzeug\local.py", line 347, in __getattr__
    return getattr(self._get_current_object(), name)
AttributeError: 'Request' object has no attribute 'arg'
2018-12-24 20:01:49,789 ERROR: Exception on /notifications [GET] [in e:\myproject\gui\venv\lib\site-packages\flask\app.py:1761]
Traceback (most recent call last):
  File "e:\myproject\gui\venv\lib\site-packages\flask\app.py", line 2292, in wsgi_app
    response = self.full_dispatch_request()
  File "e:\myproject\gui\venv\lib\site-packages\flask\app.py", line 1815, in full_dispatch_request
    rv = self.handle_user_exception(e)
  File "e:\myproject\gui\venv\lib\site-packages\flask\app.py", line 1718, in handle_user_exception
    reraise(exc_type, exc_value, tb)
  File "e:\myproject\gui\venv\lib\site-packages\flask\_compat.py", line 35, in reraise
    raise value
  File "e:\myproject\gui\venv\lib\site-packages\flask\app.py", line 1813, in full_dispatch_request
    rv = self.dispatch_request()
  File "e:\myproject\gui\venv\lib\site-packages\flask\app.py", line 1799, in dispatch_request
    return self.view_functions[rule.endpoint](**req.view_args)
  File "e:\myproject\gui\venv\lib\site-packages\flask_login\utils.py", line 261, in decorated_view
    return func(*args, **kwargs)
  File "E:\MyProject\Python\microblog\app\main\routes.py", line 198, in notifications
    since = request.arg.get('since',0.0,type=float)
  File "e:\myproject\gui\venv\lib\site-packages\werkzeug\local.py", line 347, in __getattr__
    return getattr(self._get_current_object(), name)
AttributeError: 'Request' object has no attribute 'arg'
2018-12-24 20:01:52,291 ERROR: Exception on /notifications [GET] [in e:\myproject\gui\venv\lib\site-packages\flask\app.py:1761]
Traceback (most recent call last):
  File "e:\myproject\gui\venv\lib\site-packages\flask\app.py", line 2292, in wsgi_app
    response = self.full_dispatch_request()
  File "e:\myproject\gui\venv\lib\site-packages\flask\app.py", line 1815, in full_dispatch_request
    rv = self.handle_user_exception(e)
  File "e:\myproject\gui\venv\lib\site-packages\flask\app.py", line 1718, in handle_user_exception
    reraise(exc_type, exc_value, tb)
  File "e:\myproject\gui\venv\lib\site-packages\flask\_compat.py", line 35, in reraise
    raise value
  File "e:\myproject\gui\venv\lib\site-packages\flask\app.py", line 1813, in full_dispatch_request
    rv = self.dispatch_request()
  File "e:\myproject\gui\venv\lib\site-packages\flask\app.py", line 1799, in dispatch_request
    return self.view_functions[rule.endpoint](**req.view_args)
  File "e:\myproject\gui\venv\lib\site-packages\flask_login\utils.py", line 261, in decorated_view
    return func(*args, **kwargs)
  File "E:\MyProject\Python\microblog\app\main\routes.py", line 198, in notifications
    since = request.arg.get('since',0.0,type=float)
  File "e:\myproject\gui\venv\lib\site-packages\werkzeug\local.py", line 347, in __getattr__
    return getattr(self._get_current_object(), name)
AttributeError: 'Request' object has no attribute 'arg'
2018-12-24 20:01:59,763 ERROR: Exception on /notifications [GET] [in e:\myproject\gui\venv\lib\site-packages\flask\app.py:1761]
Traceback (most recent call last):
  File "e:\myproject\gui\venv\lib\site-packages\flask\app.py", line 2292, in wsgi_app
    response = self.full_dispatch_request()
  File "e:\myproject\gui\venv\lib\site-packages\flask\app.py", line 1815, in full_dispatch_request
    rv = self.handle_user_exception(e)
  File "e:\myproject\gui\venv\lib\site-packages\flask\app.py", line 1718, in handle_user_exception
    reraise(exc_type, exc_value, tb)
  File "e:\myproject\gui\venv\lib\site-packages\flask\_compat.py", line 35, in reraise
    raise value
  File "e:\myproject\gui\venv\lib\site-packages\flask\app.py", line 1813, in full_dispatch_request
    rv = self.dispatch_request()
  File "e:\myproject\gui\venv\lib\site-packages\flask\app.py", line 1799, in dispatch_request
    return self.view_functions[rule.endpoint](**req.view_args)
  File "e:\myproject\gui\venv\lib\site-packages\flask_login\utils.py", line 261, in decorated_view
    return func(*args, **kwargs)
  File "E:\MyProject\Python\microblog\app\main\routes.py", line 198, in notifications
    since = request.arg.get('since',0.0,type=float)
  File "e:\myproject\gui\venv\lib\site-packages\werkzeug\local.py", line 347, in __getattr__
    return getattr(self._get_current_object(), name)
AttributeError: 'Request' object has no attribute 'arg'
