2018-12-21 10:38:10,319 ERROR: Exception on / [GET] [in e:\myproject\gui\venv\lib\site-packages\flask\app.py:1761]
Traceback (most recent call last):
  File "e:\myproject\gui\venv\lib\site-packages\sqlalchemy\ext\declarative\clsregistry.py", line 281, in __call__
    x = eval(self.arg, globals(), self._dict)
  File "<string>", line 1, in <module>
NameError: name 'Notification' is not defined

During handling of the above exception, another exception occurred:

Traceback (most recent call last):
  File "e:\myproject\gui\venv\lib\site-packages\flask\app.py", line 2292, in wsgi_app
    response = self.full_dispatch_request()
  File "e:\myproject\gui\venv\lib\site-packages\flask\app.py", line 1815, in full_dispatch_request
    rv = self.handle_user_exception(e)
  File "e:\myproject\gui\venv\lib\site-packages\flask\app.py", line 1718, in handle_user_exception
    reraise(exc_type, exc_value, tb)
  File "e:\myproject\gui\venv\lib\site-packages\flask\_compat.py", line 35, in reraise
    raise value
  File "e:\myproject\gui\venv\lib\site-packages\flask\app.py", line 1811, in full_dispatch_request
    rv = self.preprocess_request()
  File "e:\myproject\gui\venv\lib\site-packages\flask\app.py", line 2087, in preprocess_request
    rv = func()
  File "E:\MyProject\Python\microblog\app\main\routes.py", line 16, in before_request
    if current_user.is_authenticated:
  File "e:\myproject\gui\venv\lib\site-packages\werkzeug\local.py", line 347, in __getattr__
    return getattr(self._get_current_object(), name)
  File "e:\myproject\gui\venv\lib\site-packages\werkzeug\local.py", line 306, in _get_current_object
    return self.__local()
  File "e:\myproject\gui\venv\lib\site-packages\flask_login\utils.py", line 26, in <lambda>
    current_user = LocalProxy(lambda: _get_user())
  File "e:\myproject\gui\venv\lib\site-packages\flask_login\utils.py", line 335, in _get_user
    current_app.login_manager._load_user()
  File "e:\myproject\gui\venv\lib\site-packages\flask_login\login_manager.py", line 359, in _load_user
    return self.reload_user()
  File "e:\myproject\gui\venv\lib\site-packages\flask_login\login_manager.py", line 321, in reload_user
    user = self.user_callback(user_id)
  File "E:\MyProject\Python\microblog\app\models.py", line 137, in load_user
    return User.query.get(int(id))
  File "e:\myproject\gui\venv\lib\site-packages\flask_sqlalchemy\__init__.py", line 512, in __get__
    mapper = orm.class_mapper(type)
  File "e:\myproject\gui\venv\lib\site-packages\sqlalchemy\orm\base.py", line 421, in class_mapper
    mapper = _inspect_mapped_class(class_, configure=configure)
  File "e:\myproject\gui\venv\lib\site-packages\sqlalchemy\orm\base.py", line 400, in _inspect_mapped_class
    mapper._configure_all()
  File "e:\myproject\gui\venv\lib\site-packages\sqlalchemy\orm\mapper.py", line 1276, in _configure_all
    configure_mappers()
  File "e:\myproject\gui\venv\lib\site-packages\sqlalchemy\orm\mapper.py", line 3033, in configure_mappers
    mapper._post_configure_properties()
  File "e:\myproject\gui\venv\lib\site-packages\sqlalchemy\orm\mapper.py", line 1832, in _post_configure_properties
    prop.init()
  File "e:\myproject\gui\venv\lib\site-packages\sqlalchemy\orm\interfaces.py", line 183, in init
    self.do_init()
  File "e:\myproject\gui\venv\lib\site-packages\sqlalchemy\orm\relationships.py", line 1655, in do_init
    self._process_dependent_arguments()
  File "e:\myproject\gui\venv\lib\site-packages\sqlalchemy\orm\relationships.py", line 1712, in _process_dependent_arguments
    self.target = self.mapper.mapped_table
  File "e:\myproject\gui\venv\lib\site-packages\sqlalchemy\util\langhelpers.py", line 767, in __get__
    obj.__dict__[self.__name__] = result = self.fget(obj)
  File "e:\myproject\gui\venv\lib\site-packages\sqlalchemy\orm\relationships.py", line 1628, in mapper
    argument = self.argument()
  File "e:\myproject\gui\venv\lib\site-packages\sqlalchemy\ext\declarative\clsregistry.py", line 293, in __call__
    (self.prop.parent, self.arg, n.args[0], self.cls)
sqlalchemy.exc.InvalidRequestError: When initializing mapper Mapper|User|user, expression 'Notification' failed to locate a name ("name 'Notification' is not defined"). If this is a class name, consider adding this relationship() to the <class 'app.models.User'> class after both dependent classes have been defined.
