2018-10-31 18:02:13,770 ERROR: Exception on /search [GET][in e:\myproject\gui\venv\lib\site-packages\flask\app.py:1761]
Traceback (most recent call last):
  File "e:\myproject\gui\venv\lib\site-packages\urllib3\connection.py", line 159, in _new_conn
    (self._dns_host, self.port), self.timeout, **extra_kw)
  File "e:\myproject\gui\venv\lib\site-packages\urllib3\util\connection.py", line 80, in create_connection
    raise err
  File "e:\myproject\gui\venv\lib\site-packages\urllib3\util\connection.py", line 70, in create_connection
    sock.connect(sa)
ConnectionRefusedError: [WinError 10061] 由于目标计算机积极拒绝，无法连接。

During handling of the above exception, another exception occurred:

Traceback (most recent call last):
  File "e:\myproject\gui\venv\lib\site-packages\elasticsearch\connection\http_urllib3.py", line 172, in perform_request
    response = self.pool.urlopen(method, url, body, retries=Retry(False), headers=request_headers, **kw)
  File "e:\myproject\gui\venv\lib\site-packages\urllib3\connectionpool.py", line 638, in urlopen
    _stacktrace=sys.exc_info()[2])
  File "e:\myproject\gui\venv\lib\site-packages\urllib3\util\retry.py", line 343, in increment
    raise six.reraise(type(error), error, _stacktrace)
  File "e:\myproject\gui\venv\lib\site-packages\urllib3\packages\six.py", line 686, in reraise
    raise value
  File "e:\myproject\gui\venv\lib\site-packages\urllib3\connectionpool.py", line 600, in urlopen
    chunked=chunked)
  File "e:\myproject\gui\venv\lib\site-packages\urllib3\connectionpool.py", line 354, in _make_request
    conn.request(method, url, **httplib_request_kw)
  File "C:\Users\Administrator\AppData\Local\Programs\Python\Python36-32\lib\http\client.py", line 1239, in request
    self._send_request(method, url, body, headers, encode_chunked)
  File "C:\Users\Administrator\AppData\Local\Programs\Python\Python36-32\lib\http\client.py", line 1285, in _send_request
    self.endheaders(body, encode_chunked=encode_chunked)
  File "C:\Users\Administrator\AppData\Local\Programs\Python\Python36-32\lib\http\client.py", line 1234, in endheaders
    self._send_output(message_body, encode_chunked=encode_chunked)
  File "C:\Users\Administrator\AppData\Local\Programs\Python\Python36-32\lib\http\client.py", line 1026, in _send_output
    self.send(msg)
  File "C:\Users\Administrator\AppData\Local\Programs\Python\Python36-32\lib\http\client.py", line 964, in send
    self.connect()
  File "e:\myproject\gui\venv\lib\site-packages\urllib3\connection.py", line 181, in connect
    conn = self._new_conn()
  File "e:\myproject\gui\venv\lib\site-packages\urllib3\connection.py", line 168, in _new_conn
    self, "Failed to establish a new connection: %s" % e)
urllib3.exceptions.NewConnectionError: <urllib3.connection.HTTPConnection object at 0x050F8530>: Failed to establish a new connection: [WinError 10061] 由于目标计算机积极拒绝，无法连接。

During handling of the above exception, another exception occurred:

Traceback (most recent call last):
  File "e:\myproject\gui\venv\lib\site-packages\flask\app.py", line 2292, in wsgi_app
    response = self.full_dispatch_request()
  File "e:\myproject\gui\venv\lib\site-packages\flask\app.py", line 1815, in full_dispatch_request
    rv = self.handle_user_exception(e)
  File "e:\myproject\gui\venv\lib\site-packages\flask\app.py", line 1718, in handle_user_exception
    reraise(exc_type, exc_value, tb)
  File "e:\myproject\gui\venv\lib\site-packages\flask\_compat.py", line 35, in reraise
    raise value
  File "e:\myproject\gui\venv\lib\site-packages\flask\app.py", line 1813, in full_dispatch_request
    rv = self.dispatch_request()
  File "e:\myproject\gui\venv\lib\site-packages\flask\app.py", line 1799, in dispatch_request
    return self.view_functions[rule.endpoint](**req.view_args)
  File "e:\myproject\gui\venv\lib\site-packages\flask_login\utils.py", line 261, in decorated_view
    return func(*args, **kwargs)
  File "E:\MyProject\Python\microblog\app\main\routes.py", line 139, in search
    current_app.config['POSTS_PER_PAGE'])
  File "E:\MyProject\Python\microblog\app\models.py", line 14, in search
    ids, total = query_index(cls.__tablename__, expression, page, per_page)
  File "E:\MyProject\Python\microblog\app\search.py", line 23, in query_index
    'from':(page - 1) * per_page,'size': per_page})
  File "e:\myproject\gui\venv\lib\site-packages\elasticsearch\client\utils.py", line 76, in _wrapped
    return func(*args, params=params, **kwargs)
  File "e:\myproject\gui\venv\lib\site-packages\elasticsearch\client\__init__.py", line 660, in search
    doc_type, '_search'), params=params, body=body)
  File "e:\myproject\gui\venv\lib\site-packages\elasticsearch\transport.py", line 318, in perform_request
    status, headers_response, data = connection.perform_request(method, url, params, body, headers=headers, ignore=ignore, timeout=timeout)
  File "e:\myproject\gui\venv\lib\site-packages\elasticsearch\connection\http_urllib3.py", line 181, in perform_request
    raise ConnectionError('N/A', str(e), e)
elasticsearch.exceptions.ConnectionError: ConnectionError(<urllib3.connection.HTTPConnection object at 0x050F8530>: Failed to establish a new connection: [WinError 10061] 由于目标计算机积极拒绝，无法连接。) caused by: NewConnectionError(<urllib3.connection.HTTPConnection object at 0x050F8530>: Failed to establish a new connection: [WinError 10061] 由于目标计算机积极拒绝，无法连接。)
2018-10-31 18:04:22,386 INFO: Microblog startup[in E:\MyProject\Python\microblog\app\__init__.py:78]
2018-10-31 18:04:29,194 ERROR: Exception on /search [GET][in e:\myproject\gui\venv\lib\site-packages\flask\app.py:1761]
Traceback (most recent call last):
  File "e:\myproject\gui\venv\lib\site-packages\flask\app.py", line 2292, in wsgi_app
    response = self.full_dispatch_request()
  File "e:\myproject\gui\venv\lib\site-packages\flask\app.py", line 1815, in full_dispatch_request
    rv = self.handle_user_exception(e)
  File "e:\myproject\gui\venv\lib\site-packages\flask\app.py", line 1718, in handle_user_exception
    reraise(exc_type, exc_value, tb)
  File "e:\myproject\gui\venv\lib\site-packages\flask\_compat.py", line 35, in reraise
    raise value
  File "e:\myproject\gui\venv\lib\site-packages\flask\app.py", line 1813, in full_dispatch_request
    rv = self.dispatch_request()
  File "e:\myproject\gui\venv\lib\site-packages\flask\app.py", line 1799, in dispatch_request
    return self.view_functions[rule.endpoint](**req.view_args)
  File "e:\myproject\gui\venv\lib\site-packages\flask_login\utils.py", line 261, in decorated_view
    return func(*args, **kwargs)
  File "E:\MyProject\Python\microblog\app\main\routes.py", line 139, in search
    current_app.config['POSTS_PER_PAGE'])
  File "E:\MyProject\Python\microblog\app\models.py", line 14, in search
    ids, total = query_index(cls.__tablename__, expression, page, per_page)
  File "E:\MyProject\Python\microblog\app\search.py", line 23, in query_index
    'from':(page - 1) * per_page,'size': per_page})
  File "e:\myproject\gui\venv\lib\site-packages\elasticsearch\client\utils.py", line 76, in _wrapped
    return func(*args, params=params, **kwargs)
  File "e:\myproject\gui\venv\lib\site-packages\elasticsearch\client\__init__.py", line 660, in search
    doc_type, '_search'), params=params, body=body)
  File "e:\myproject\gui\venv\lib\site-packages\elasticsearch\transport.py", line 318, in perform_request
    status, headers_response, data = connection.perform_request(method, url, params, body, headers=headers, ignore=ignore, timeout=timeout)
  File "e:\myproject\gui\venv\lib\site-packages\elasticsearch\connection\http_urllib3.py", line 186, in perform_request
    self._raise_error(response.status, raw_data)
  File "e:\myproject\gui\venv\lib\site-packages\elasticsearch\connection\base.py", line 125, in _raise_error
    raise HTTP_EXCEPTIONS.get(status_code, TransportError)(status_code, error_message, additional_info)
elasticsearch.exceptions.NotFoundError: NotFoundError(404, 'index_not_found_exception', 'no such index')
